#VRML_SIM R2019a utf8
WorldInfo {
}
Viewpoint {
  orientation 0.3486638467664331 -0.8770218414091893 -0.3305544004385181 4.653165736285463
  position 0.5432616635976439 0.6797376772154516 -0.06307694420927593
}
TexturedBackground {
}
TexturedBackgroundLight {
}
Floor {
}
Robot {
  translation 0 0.2 0
  children [
    DEF ROBOT_BODY Shape {
      appearance PBRAppearance {
        baseColor 0.9869535362783246 0.1892576485847257 0.11616693369954986
      }
      geometry DEF G_BODY Box {
        size 0.25 0.07 0.1
      }
    }
    DEF WHEEL1_JOINT HingeJoint {
      jointParameters HingeJointParameters {
        axis 0 0 1
        anchor -0.05 0 0.06
      }
      device [
        RotationalMotor {
          name "motor_right"
        }
      ]
      endPoint DEF WHEEL1 Solid {
        translation -0.05 0 0.06
        rotation -1 0 0 1.5707996938995745
        children [
          Shape {
            appearance DEF C_WHEEL PBRAppearance {
              baseColor 0 0 0
              roughness 1
              metalness 0
            }
            geometry DEF G_WHEEL Cylinder {
              height 0.02
              radius 0.075
            }
          }
        ]
        boundingObject USE G_WHEEL
        physics Physics {
        }
      }
    }
  ]
  boundingObject USE G_BODY
  physics Physics {
  }
}
